<?xml version="1.0"?>
<robot name="runding">

<material name="blue">
    <color rgba="0 0 0.8 1"/>
  </material>
  
  <link name="stamme_link">
    <visual>
      <geometry>
        <cylinder length="0.01" radius="0.01"/>
      </geometry>
      <origin rpy="0 0 0" xyz="0 0 0.5"/>
    </visual>
  </link>
  
  <link name="plate_link">
    <visual>
      <geometry>
        <cylinder length="0.1" radius="1"/>
      </geometry>
      <origin rpy="0 0 0" xyz="0 0 0.01"/>
      <material name="blue"/>
    </visual>
  </link>
  
  <joint name="swivel" type="floating">
    <origin xyz="0 0 0.01" />
    <axis xyz="1 1 0" />
    <parent link="stamme_link"/>
    <child link="plate_link"/>
    <limit upper="0" lower="-.5" effort="10" velocity="10" />
  </joint>
  
    
</robot>

